<?xml version="1.0" encoding="UTF-8"?>
<robot xmlns:xacro="http://ros.org/wiki/xacro">
    <xacro:macro name="wamv_mavlink" params="name:=mavlink">

        <link name="gps::link">
            <visual name="${name}_visual">
                <geometry>
                    <box size="0.0005 0.00025 0.005" />
                </geometry>
            </visual>
            <inertial>
                <mass value="0.1"/>
                <inertia ixx="0.000083" ixy="0.0" ixz="0.0" iyy="0.000083" iyz="0.0" izz="0.0125"/>
            </inertial>
        </link>

        <joint name="gps_joint" type="revolute">
            <parent link="${namespace}/base_link" />
            <child link="gps::link" />
            <axis xyz="0 0 1"/>
            <limit lower="${-pi}" upper="${pi}" effort="10" velocity="0.01"/>
            <origin xyz="0 0 0" rpy="0 0 0"/>
        </joint>

        <gazebo reference="gps::link">
            <sensor name="gps" type="gps">
                <update_rate>5.0</update_rate>
                <always_on>true</always_on>
                <visualize>false</visualize>
                <plugin name="mavlink_gps_plugin" filename="libgazebo_gps_plugin.so">
                    <robotNamespace/>
                    <gpsNoise>true</gpsNoise>
                    <gpsXYRandomWalk>2.0</gpsXYRandomWalk>
                    <gpsZRandomWalk>4.0</gpsZRandomWalk>
                    <gpsXYNoiseDensity>2.0e-4</gpsXYNoiseDensity>
                    <gpsZNoiseDensity>4.0e-4</gpsZNoiseDensity>
                    <gpsVXYNoiseDensity>0.2</gpsVXYNoiseDensity>
                    <gpsVZNoiseDensity>0.4</gpsVZNoiseDensity>
                </plugin>
            </sensor>
        </gazebo>

        <gazebo>

            <plugin name="barometer_plugin" filename="libgazebo_barometer_plugin.so">
                <robotNamespace/>
                <pubRate>50</pubRate>
                <baroTopic>/baro</baroTopic>
                <baroDriftPaPerSec>0</baroDriftPaPerSec>
            </plugin>

            <plugin name="magnetometer_plugin" filename="libgazebo_magnetometer_plugin.so">
                <robotNamespace/>
                <pubRate>100</pubRate>
                <noiseDensity>0.0004</noiseDensity>
                <randomWalk>6.4e-06</randomWalk>
                <biasCorrelationTime>600</biasCorrelationTime>
                <magTopic>/mag</magTopic>
            </plugin>

            <plugin name="groundtruth_plugin" filename="libgazebo_groundtruth_plugin.so">
                <robotNamespace/>
            </plugin>

            <plugin name="gazebo_imu_plugin" filename="libgazebo_imu_plugin.so">
                <robotNamespace></robotNamespace>
                <linkName>${namespace}/base_link</linkName>
                <imuTopic>/imu</imuTopic>
                <gyroscopeNoiseDensity>0.0003394</gyroscopeNoiseDensity>
                <gyroscopeRandomWalk>3.8785e-05</gyroscopeRandomWalk>
                <gyroscopeBiasCorrelationTime>1000.0</gyroscopeBiasCorrelationTime>
                <gyroscopeTurnOnBiasSigma>0.0087</gyroscopeTurnOnBiasSigma>
                <accelerometerNoiseDensity>0.004</accelerometerNoiseDensity>
                <accelerometerRandomWalk>0.006</accelerometerRandomWalk>
                <accelerometerBiasCorrelationTime>300.0</accelerometerBiasCorrelationTime>
                <accelerometerTurnOnBiasSigma>0.196</accelerometerTurnOnBiasSigma>
            </plugin>

            <plugin name="mavlink_interface" filename="libgazebo_mavlink_interface.so">
                <robotNamespace></robotNamespace>
                <imuSubTopic>/imu</imuSubTopic>
                <magSubTopic>/mag</magSubTopic>
                <baroSubTopic>/baro</baroSubTopic>
                <mavlink_addr>INADDR_ANY</mavlink_addr>
                <mavlink_tcp_port>4560</mavlink_tcp_port>
                <mavlink_udp_port>14560</mavlink_udp_port>
                <serialEnabled>0</serialEnabled>
                <serialDevice>/dev/ttyACM0</serialDevice>
                <baudRate>921600</baudRate>
                <qgc_addr>INADDR_ANY</qgc_addr>
                <qgc_udp_port>14550</qgc_udp_port>
                <sdk_addr>INADDR_ANY</sdk_addr>
                <sdk_udp_port>14540</sdk_udp_port>
                <hil_mode>0</hil_mode>
                <hil_state_level>false</hil_state_level>
                <enable_lockstep>true</enable_lockstep>
                <use_tcp>1</use_tcp>
                <motorSpeedCommandPubTopic>/gazebo/command/motor_speed</motorSpeedCommandPubTopic>
                <control_channels>
                    <channel name="left_rotor">
                        <input_index>0</input_index>
                        <input_offset>0</input_offset>
                        <input_scaling>100</input_scaling>
                        <zero_position_disarmed>0</zero_position_disarmed>
                        <zero_position_armed>0</zero_position_armed>
                        <joint_control_type>velocity</joint_control_type>
                        <joint_name>${namespace}/left_engine_propeller_joint</joint_name>
                    </channel>
                    <channel name="right_rotor">
                        <input_index>1</input_index>
                        <input_offset>0</input_offset>
                        <input_scaling>100</input_scaling>
                        <zero_position_disarmed>0</zero_position_disarmed>
                        <zero_position_armed>0</zero_position_armed>
                        <joint_control_type>velocity</joint_control_type>
                        <joint_name>${namespace}/right_engine_propeller_joint</joint_name>
                    </channel>
                </control_channels>
            </plugin>

        </gazebo>
    </xacro:macro>
</robot>
